Workbook

Sheet Theory (day-wise)
A1: Placement Prep — Theory, day-wise (13 Oct–3 Nov · Must + Important) | F1: ="Rows done: "&COUNTIF(K7:K83,"Done")&" / "&COUNTA(K7:K83)&" ("&TEXT(COUNTIF(K7:K83,"Done")/COUNTA(K7:K83),"0%")&")" -> Rows done: 0 / 77 (0%)
A2: Sorted by date (13 Oct → 3 Nov). One row per topic. SUFFICIENT = must-do, enough on its own (your own files first; external only where they don't cover the topic). ADD-ON = optional extra depth, only if time permits.
A3: CampusX ML #n = position in your 100 Days of ML playlist. Mitesh L = CS7015 lecture, M = module. TuteDude Module/L = module and lecture. CWH § = CodeWithHarry DS course section. QB § = Interview Question Bank section.
A4: Red [External] = not in your project files. Est. hrs counts sufficient resources only (1.5× playback + short notes). Edit any estimate and the 'Daily load' tab recalculates. Bold date = first topic of that day.
A6: # | B6: Date | C6: Topic | D6: Syllabus area | E6: Priority | F6: Sufficient resource (full name) | G6: What to follow — sufficient resource | H6: Add-on content resource (full name) | I6: What to follow in add-on resource | J6: Est. hrs | K6: Status | L6: Notes
A7: 1 | B7: 46308 | C7: Conditional probability, Bayes (two-coin problems), expectation | D7: 7. Probability & statistics | E7: Must | F7: 1. CodeWithHarry — The Ultimate Job Ready Data Science Course 2. CampusX — Probability Basics (ML Roadmap 2022) (playlist, 10 videos) 3. Interview Question Bank (your project file) | G7: 1. §12 Probability — all 7 lectures (Intro → Bayes' Theorem), 70 min 2. Only the random-variable & expectation videos 3. §7 Probability problems — Netradyne two-coin ×3, Mastercard/Myntra Bayes, MAIG dice, expected tosses | H7: 1. CampusX — 100 Days of Machine Learning (YouTube playlist, 134 videos) 2. CampusX — Probability Basics (ML Roadmap 2022) (playlist, 10 videos) 3. Blitzstein & Hwang — Introduction to Probability (free PDF, Harvard Stat 110) [External] | I7: 1. #82 Conditional Probability · #83 Independent Events · #84 Mutually Exclusive · #85 Bayes Theorem · #86 Bayes problem 2. Remaining videos 3. Ch 2 Conditional probability · Ch 9.1–9.3 Conditional expectation (expected tosses to HH) | J7: 2.75 | K7: Not started
A8: 2 | B8: 46308 | C8: Distributions (Bernoulli → exponential) & CLT | D8: 7. Probability & statistics | E8: Must | F8: 1. CodeWithHarry — The Ultimate Job Ready Data Science Course 2. Blitzstein & Hwang — Introduction to Probability (free PDF, Harvard Stat 110) [External] 3. Interview Question Bank (your project file) | G8: 1. §13 Probability Distributions & CLT — all 5 lectures (Uniform, Binomial, Normal, CLT), 35 min 2. Ch 4.3 Poisson · Ch 5.5–5.6 Exponential & memorylessness (not covered in your courses) 3. §7 Distributions — Meesho exponential + CLT, Citi CLT, Goldman min of exponentials | H8: 1. CampusX — Statistics for Machine Learning (course, 13 lessons) 2. StatQuest with Josh Starmer (YouTube) [External] | I8: 1. Lessons on distributions, sampling distribution and CLT 2. 'The Main Ideas behind Probability Distributions' · 'The Central Limit Theorem, Clearly Explained' | J8: 2 | K8: Not started
A9: 3 | B9: 46309 | C9: Simulation: sampling from a PMF, fair coin from biased coin | D9: 7. Probability & statistics | E9: Must | F9: Interview Question Bank (your project file) | G9: §7 Netradyne cointoss → [a,b] & 4/5/9 generator · InMobi fair coin from biased · Intuit PMF / simulate π (solve on paper; code is in the Coding tab) | H9: — | I9: — | J9: 0.75 | K9: Not started | L9: Theory on paper today; the code version sits in the Coding tab
A10: 4 | B10: 46309 | C10: MLE derivations; MAP & link to regularization | D10: 7. Probability & statistics | E10: Must | F10: 1. CampusX — 100 Days of Machine Learning (YouTube playlist, 134 videos) 2. Stanford CS229 Lecture Notes — Andrew Ng (free PDF) [External] 3. Interview Question Bank (your project file) | G10: 1. #73 Logistic Regression Part 4 — Loss Function, Maximum Likelihood, BCE 2. Ch 9 — 'Bayesian statistics and regularization' (MAP; ridge = Gaussian prior) 3. §7 Rapido MLE pseudocode · Wells Fargo & Goldman likelihood · CRED MAP/MLE | H10: StatQuest with Josh Starmer (YouTube) [External] | I10: 'Maximum Likelihood, clearly explained!!!' · 'Maximum Likelihood for the Normal Distribution' | J10: 1.5 | K10: Not started
A11: 5 | B11: 46309 | C11: Hypothesis testing: p-values, type I/II, t vs z, one vs two-tailed | D11: 7. Probability & statistics | E11: Must | F11: 1. CampusX — Advance Statistics (ML Roadmap 2022) (playlist, 7 videos) 2. Interview Question Bank (your project file) | G11: 1. All 7 videos 2. §7 Hypothesis testing — Meesho salary t-test, Airtel p-value for a layperson, Razorpay | H11: 1. Penn State STAT 500 — Applied Statistics (online notes) [External] 2. StatQuest with Josh Starmer (YouTube) [External] | I11: 1. Lesson 6a & 6b Hypothesis testing · Lesson 7 Comparing two populations (t-tests) 2. 'p-values: What they are and how to interpret them' | J11: 2.75 | K11: Not started
A12: 6 | B12: 46309 | C12: Confidence intervals & A/B test design | D12: 7. Probability & statistics | E12: Must | F12: 1. Penn State STAT 500 — Applied Statistics (online notes) [External] 2. Udacity — A/B Testing by Google (free course) [External] 3. Interview Question Bank (your project file) | G12: 1. Lesson 5 Confidence intervals 2. Lesson 1 Overview · Lesson 4 Designing an experiment 3. §7 MAIG confidence interval · §11 Rapido A/B split & test choice | H12: Udacity — A/B Testing by Google (free course) [External] | I12: Lesson 3 Choosing & characterizing metrics · Lesson 2 Policy & ethics (skim) | J12: 2 | K12: Not started
A13: 7 | B13: 46310 | C13: Data prep: feature scaling & encoding, pipelines | D13: 1. Classical ML | E13: Must | F13: CampusX — 100 Days of Machine Learning (YouTube playlist, 134 videos) | G13: #23 What is Feature Engineering · #24 Standardization · #25 Normalization · #26 Ordinal/Label Encoding · #27 One-Hot Encoding · #28 Column Transformer · #29 ML Pipelines A–Z | H13: 1. TuteDude — Generative AI course 2. CodeWithHarry — The Ultimate Job Ready Data Science Course | I13: 1. Module 12 — L16 Feature Engineering · L17 Feature Encoding · L18 One Hot Encoder · L19 Feature Scaling · L20 Column Transformer · L21 ML Pipeline 2. §16 Practical ML — 'Handling Categorical values', 'Feature scaling in sklearn', 'Constructing Pipelines', 'ColumnTransformer…' | J13: 2.75 | K13: Not started
A14: 8 | B14: 46310 | C14: Data prep: missing values & outliers | D14: 1. Classical ML | E14: Must | F14: CampusX — 100 Days of Machine Learning (YouTube playlist, 134 videos) | G14: #35 Complete Case Analysis · #36 Simple Imputer · #37 Missing categorical · #39 KNN Imputer · #41 What are Outliers · #42 Z-score · #43 IQR | H14: 1. CampusX — 100 Days of Machine Learning (YouTube playlist, 134 videos) 2. CodeWithHarry — The Ultimate Job Ready Data Science Course 3. TuteDude — Generative AI course | I14: 1. #40 MICE · #44 Percentile / Winsorization 2. §16 — 'Further Preprocessing & Handling Missing Data' 3. Module 12 — L11 Data Cleaning · L13 Automated Data Cleaning · L14–15 EDA steps | J14: 2 | K14: Not started
A15: 9 | B15: 46310 | C15: Data prep: multicollinearity & VIF | D15: 1. Classical ML | E15: Must | F15: 1. Penn State STAT 501 — Regression Methods (online notes) [External] 2. Interview Question Bank (your project file) | G15: 1. Lesson 12: Multicollinearity — 12.3 & 12.4 (detecting with VIF) 2. §1 Feature engineering — Intuit VIF/correlation Qs (3), Airtel VIF, Wells Fargo correlated features | H15: — | I15: — | J15: 0.75 | K15: Not started
A16: 10 | B16: 46310 | C16: Data prep: cross-validation & data leakage | D16: 1. Classical ML | E16: Must | F16: 1. TuteDude — Generative AI course 2. scikit-learn User Guide / examples [External] 3. Interview Question Bank (your project file) | G16: 1. Module 12 — L22 Train vs Validation vs Test Data & Cross Validation 2. 'Common pitfalls and recommended practices' → Data leakage section 3. §1 Feature engineering & data preparation — all 15 Qs (Intuit scaler-before-split, Razorpay full pipeline) | H16: 1. CodeWithHarry — The Ultimate Job Ready Data Science Course 2. StatQuest with Josh Starmer (YouTube) [External] | I16: 1. §16 — 'Creating a Test Set' · 'Stratified Shuffle Split' 2. 'Machine Learning Fundamentals: Cross Validation' | J16: 1.5 | K16: Not started
A17: 11 | B17: 46311 | C17: Linear regression (part 1): intuition, maths, assumptions, MLE view | D17: 1. Classical ML | E17: Must | F17: 1. CampusX — 100 Days of Machine Learning (YouTube playlist, 134 videos) 2. Stanford CS229 Lecture Notes — Andrew Ng (free PDF) [External] 3. Interview Question Bank (your project file) | G17: 1. #50 Simple LR · #51 Simple LR maths from scratch · #53 Multiple LR intuition · #54 Multiple LR maths · #55 Multiple LR code · #56 Assumptions of LR 2. Ch 1.3 Probabilistic interpretation (MLE view — not in your courses) 3. §1 Linear regression — all 20 Qs | H17: 1. TuteDude — Generative AI course 2. CampusX — Linear Regression – Updated 2022 (course, 6 lessons) 3. Stanford CS229 Lecture Notes — Andrew Ng (free PDF) [External] | I17: 1. Module 12 — L23 Linear Regression 2. Quick revision only 3. Ch 1.1 LMS algorithm · 1.2 Normal equations | J17: 3.25 | K17: Not started
A18: 12 | B18: 46311 | C18: Linear regression (part 2): gradient descent — batch, SGD, mini-batch | D18: 1. Classical ML | E18: Must | F18: CampusX — 100 Days of Machine Learning (YouTube playlist, 134 videos) | G18: #57 Gradient Descent from scratch · #58 Batch GD · #59 Stochastic GD · #60 Mini-batch GD | H18: — | I18: — | J18: 2.75 | K18: Not started | L18: Long videos (#57 is 2 h) — 1.25–1.5× speed is fine
A19: 13 | B19: 46312 | C19: Bias–variance tradeoff & fixing overfitting | D19: 1. Classical ML | E19: Must | F19: 1. CampusX — 100 Days of Machine Learning (YouTube playlist, 134 videos) 2. Mitesh M. Khapra — CS7015 Deep Learning, IIT Madras (YouTube videos + slides) 3. Interview Question Bank (your project file) | G19: 1. #61 Polynomial Regression · #62 Bias–Variance Trade-off 2. Lecture 8 — M1 Bias and Variance · M2 Train error vs test error 3. §1 Bias–variance & overfitting — all 13 Qs | H19: TuteDude — Generative AI course | I19: Module 12 — L25 Overfitting, Underfitting, Variance & Bias | J19: 1.25 | K19: Not started
A20: 14 | B20: 46312 | C20: L1 vs L2: sparsity geometry, ridge as Gaussian prior | D20: 1. Classical ML | E20: Must | F20: 1. CampusX — 100 Days of Machine Learning (YouTube playlist, 134 videos) 2. Interview Question Bank (your project file) | G20: 1. #63 Ridge Part 1 · #64 Ridge Part 2 (maths) · #65 Ridge Part 3 (GD) · #66 5 Key Points · #67 Lasso · #68 Why Lasso creates sparsity 2. §1 Regularization — all 19 Qs (Gaussian-prior view: see your MAP notes) | H20: 1. CampusX — 100 Days of Machine Learning (YouTube playlist, 134 videos) 2. CampusX — Regularization (course, 7 lessons) | I20: 1. #69 ElasticNet 2. Revision only | J20: 2.75 | K20: Not started
A21: 15 | B21: 46312 | C21: Logistic regression (part 1): perceptron trick, sigmoid, BCE, GD | D21: 1. Classical ML | E21: Must | F21: CampusX — 100 Days of Machine Learning (YouTube playlist, 134 videos) | G21: #70 Perceptron Trick · #71 Perceptron code · #72 Sigmoid · #74 Derivative of Sigmoid · #75 GD & code from scratch (#73 already done with MLE) | H21: 1. TuteDude — Generative AI course 2. Stanford CS229 Lecture Notes — Andrew Ng (free PDF) [External] | I21: 1. Module 12 — L26 Logistic Regression 2. Ch 2 Classification & logistic regression (derivation) | J21: 2.5 | K21: Not started
A22: 16 | B22: 46313 | C22: Logistic regression (part 2): softmax, 'why linear', convexity | D22: 1. Classical ML | E22: Must | F22: 1. CampusX — 100 Days of Machine Learning (YouTube playlist, 134 videos) 2. Interview Question Bank (your project file) | G22: 1. #79 Softmax Regression 2. §1 Logistic regression — all 30 Qs | H22: 1. CampusX — 100 Days of Machine Learning (YouTube playlist, 134 videos) 2. CampusX — Logistic Regression (Updated) (course, 9 lessons) 3. Stanford CS229 Lecture Notes — Andrew Ng (free PDF) [External] | I22: 1. #80 Polynomial Features in LR · #81 LR Hyperparameters 2. Revision only 3. Ch 3 GLMs → softmax regression | J22: 1.5 | K22: Not started
A23: 17 | B23: 46313 | C23: Confusion matrix, precision / recall / F1, accuracy on imbalance | D23: 2. Model evaluation & metrics | E23: Must | F23: CampusX — 100 Days of Machine Learning (YouTube playlist, 134 videos) | G23: #76 Accuracy & Confusion Matrix, Type 1/2 errors · #77 Precision, Recall & F1 | H23: 1. TuteDude — Generative AI course 2. CodeWithHarry — The Ultimate Job Ready Data Science Course | I23: 1. Module 12 — L27 Classification Metrics 2. §16 — 'Measuring Accuracy of our Predictions' | J23: 1.5 | K23: Not started
A24: 18 | B24: 46313 | C24: ROC-AUC vs PR-AUC, threshold choice, AUC = 0.2 | D24: 2. Model evaluation & metrics | E24: Must | F24: 1. CampusX — 100 Days of Machine Learning (YouTube playlist, 134 videos) 2. scikit-learn User Guide / examples [External] 3. Interview Question Bank (your project file) | G24: 1. #78 ROC Curve & ROC-AUC 2. 'Precision-Recall' example (PR curve, average precision — not in your courses) 3. §2 Model evaluation & metrics — all 33 Qs | H24: StatQuest with Josh Starmer (YouTube) [External] | I24: 'ROC and AUC, Clearly Explained!' | J24: 2 | K24: Not started
A25: 19 | B25: 46313 | C25: Regression metrics: MSE, MAE, RMSE, R², adjusted R² | D25: 2. Model evaluation & metrics | E25: Must | F25: CampusX — 100 Days of Machine Learning (YouTube playlist, 134 videos) | G25: #52 Regression Metrics – MSE, MAE, RMSE, R² & Adjusted R² | H25: 1. TuteDude — Generative AI course 2. CodeWithHarry — The Ultimate Job Ready Data Science Course | I25: 1. Module 12 — L24 Metrics in Regression 2. §16 — 'Measuring Errors (RMSE & MAE)' | J25: 0.5 | K25: Not started
A26: 20 | B26: 46313 | C26: Class imbalance: SMOTE, class weights, choosing a metric | D26: 1. Classical ML | E26: Must | F26: 1. CampusX — 100 Days of Machine Learning (YouTube playlist, 134 videos) 2. Interview Question Bank (your project file) | G26: 1. #133 Imbalanced Data – Undersampling, Oversampling, SMOTE 2. §1 Imbalanced data — all 11 Qs | H26: imbalanced-learn User Guide [External] | I26: 'Over-sampling' → SMOTE section | J26: 1.25 | K26: Not started
A27: 21 | B27: 46314 | C27: Trees: Gini / entropy, continuous splits, regression trees | D27: 1. Classical ML | E27: Must | F27: CampusX — 100 Days of Machine Learning (YouTube playlist, 134 videos) | G27: #97 Decision Trees – Entropy, Gini, Information Gain · #98 DT Hyperparameters & overfitting · #99 Regression Trees | H27: 1. TuteDude — Generative AI course 2. StatQuest with Josh Starmer (YouTube) [External] | I27: 1. Module 12 — L31 Decision Tree Algorithm 2. 'Decision and Classification Trees, Clearly Explained' · 'Regression Trees, Clearly Explained' | J27: 1.75 | K27: Not started
A28: 22 | B28: 46314 | C28: Ensembles (part 1): bagging & random forest | D28: 1. Classical ML | E28: Must | F28: CampusX — 100 Days of Machine Learning (YouTube playlist, 134 videos) | G28: #101 Intro to Ensembles · #105 Bagging Part 1 · #108 Intro to Random Forest · #109 RF Bias–Variance · #110 Bagging vs RF · #113 OOB Score · #114 Feature Importance | H28: 1. TuteDude — Generative AI course 2. StatQuest with Josh Starmer (YouTube) [External] | I28: 1. Module 12 — L32 Bagging vs Boosting & Random Forest 2. 'Random Forests Part 1' | J28: 2.5 | K28: Not started
A29: 23 | B29: 46314 | C29: Ensembles (part 2): boosting, gradient boosting, XGBoost intuition | D29: 1. Classical ML | E29: Must | F29: 1. CampusX — 100 Days of Machine Learning (YouTube playlist, 134 videos) 2. Interview Question Bank (your project file) | G29: 1. #119 Bagging vs Boosting · #120 Gradient Boosting Explained · #122 GB for Classification · #123 Introduction to XGBoost 2. §1 Decision trees & ensembles — all 26 Qs | H29: 1. CampusX — 100 Days of Machine Learning (YouTube playlist, 134 videos) 2. StatQuest with Josh Starmer (YouTube) [External] | I29: 1. #121 Maths of Gradient Boosting · #124–126 XGBoost regression / classification / maths 2. 'Gradient Boost Part 1' · 'XGBoost Part 1' | J29: 3 | K29: Not started
A30: 24 | B30: 46315 | C30: Perceptron → MLP → feedforward networks | D30: 3. Deep learning fundamentals | E30: Must | F30: Mitesh M. Khapra — CS7015 Deep Learning, IIT Madras (YouTube videos + slides) | G30: Lecture 2 — M1–M8 (McCulloch–Pitts, perceptron, learning algorithm, MLPs) · Lecture 3 — M1–M5 (sigmoid neuron, GD, FNNs) | H30: TuteDude — Generative AI course | I30: Module 14 — L3 Perceptron · L4 Multi Layered Perceptron | J30: 2 | K30: Not started
... A52: 46 | B52: 46321 | C52: Hallucination causes & mitigation; RAG vs fine-tuning | D52: 6. GenAI, LLMs & RAG | E52: Must | F52: 1. TuteDude — Generative AI course 2. Lilian Weng — 'Extrinsic Hallucinations in LLMs' (blog) [External] 3. Interview Question Bank (your project file) | G52: 1. Module 29 — L5 What is RAG (Shifting from Fine-Tuning to RAG) 2. Causes + 'Anti-hallucination methods' sections 3. §6 Walmart/Citi hallucination · Oracle & Lam RAG vs fine-tuning | H52: — | I52: — | J52: 1.25 | K52: Not started
A53: 47 | B53: 46321 | C53: LoRA / QLoRA & quantization basics | D53: 6. GenAI, LLMs & RAG | E53: Must | F53: 1. Hugging Face PEFT docs [External] 2. Hugging Face blog — '4-bit quantization and QLoRA' (bitsandbytes) [External] 3. Interview Question Bank (your project file) | G53: 1. Conceptual guide 'LoRA' 2. Whole post 3. §6 Lam LoRA–SVD link · Qualcomm QLoRA pipeline · Fujitsu quantization | H53: Sebastian Raschka — 'Practical Tips for Finetuning LLMs Using LoRA' (blog) [External] | I53: Whole post (rank r, alpha, which layers) | J53: 1.5 | K53: Not started | L53: Not covered in your courses — external is the sufficient resource
A54: 48 | B54: 46321 | C54: Case framework: goal → metric → data → baseline → eval → deploy & monitor | D54: 11. Case studies & ML system design | E54: Must | F54: CampusX — Machine Learning Case Study (playlist, 2 videos) | G54: Both videos | H54: 1. CampusX — Data Science Interview Preparation (playlist, 2 videos) 2. CampusX — Machine Learning Interview Questions (playlist, 22 videos) | I54: 1. Both videos 2. Selective — case / scenario videos | J54: 1.5 | K54: Not started
A55: 49 | B55: 46322 | C55: Case practice: fraud detection & churn prediction | D55: 11. Case studies & ML system design | E55: Must | F55: Interview Question Bank (your project file) | G55: §11 Mastercard fraud ×3 · ZS Associates fraud pipeline ×3 · Netradyne real-time issues · Airtel churn · Capital One unsubscribe reasons — write full answers using the framework | H55: — | I55: — | J55: 1.75 | K55: Not started
A56: 50 | B56: 46322 | C56: Case practice: demand forecasting, metric drop & A/B design | D56: 11. Case studies & ML system design | E56: Must | F56: Interview Question Bank (your project file) | G56: §11 Intuit Flipkart next-day customers · Rapido acquisition · Rapido Zomato −15% (×2) · Rapido price-sensitive segments + A/B validation | H56: — | I56: — | J56: 1.5 | K56: Not started
A57: 51 | B57: 46322 | C57: Sums of RVs, birthday problem, recursive puzzles | D57: 7. Probability & statistics | E57: Important | F57: 1. Blitzstein & Hwang — Introduction to Probability (free PDF, Harvard Stat 110) [External] 2. Interview Question Bank (your project file) | G57: 1. Ch 8.2 Convolutions (X+Y) · Ch 1.6 birthday problem 2. §7 Intuit birthday 400/366 · Netradyne amoeba & PDF of X+Y · Wells Fargo U+U & dice game · Goldman A vs B dice | H57: Brainstellar — probability puzzles (website) [External] | I57: Easy + medium puzzles (first-step analysis) | J57: 2.25 | K57: Not started
A58: 52 | B58: 46323 | C58: Chi-square & ANOVA | D58: 7. Probability & statistics | E58: Important | F58: CampusX — Statistics for Machine Learning (course, 13 lessons) | G58: Chi-square & ANOVA lessons | H58: Penn State STAT 500 — Applied Statistics (online notes) [External] | I58: Lesson 8 Chi-square test for independence · Lesson 10 One-way ANOVA | J58: 1.25 | K58: Not started
A59: 53 | B59: 46323 | C59: Inverse-CDF sampling, unbiased estimators, correlation vs causation | D59: 7. Probability & statistics | E59: Important | F59: 1. Blitzstein & Hwang — Introduction to Probability (free PDF, Harvard Stat 110) [External] 2. StatQuest with Josh Starmer (YouTube) [External] 3. Interview Question Bank (your project file) | G59: 1. Ch 5.3 Universality of the Uniform (inverse-CDF sampling) 2. 'Why Dividing By N Underestimates the Variance' 3. §7 Goldman sampling from CDF & unbiased estimators · Netradyne regression vs correlation | H59: — | I59: — | J59: 1.25 | K59: Not started
A60: 54 | B60: 46323 | C60: SPD matrices, rank & null space; least squares & normal equations | D60: 8. Linear algebra, calculus & optimization | E60: Important | F60: 1. CampusX — Linear Algebra for Machine Learning (playlist, 8 videos) 2. Stanford CS229 Lecture Notes — Andrew Ng (free PDF) [External] 3. Interview Question Bank (your project file) | G60: 1. Rank / null space / positive-definite videos 2. Ch 1.2 The normal equations 3. §8 Intuit SPD (eigenvalues of A⁻¹) · Wells Fargo diagonalization f(A) | H60: 1. 3Blue1Brown — Essence of Linear Algebra (YouTube) [External] 2. MIT 18.06 Linear Algebra — Gilbert Strang (OCW) [External] | I60: 1. Ch 7 Inverse matrices, column space and null space 2. Lecture 15 Projections · Lecture 16 Least squares | J60: 1.5 | K60: Not started
A61: 55 | B61: 46323 | C61: Lagrange multipliers (SVM dual); Newton's method idea | D61: 8. Linear algebra, calculus & optimization | E61: Important | F61: 1. Khan Academy — Multivariable calculus [External] 2. Stanford CS229 Lecture Notes — Andrew Ng (free PDF) [External] | G61: 1. 'Lagrange multipliers, introduction' (+ example) 2. Ch 2 — Newton's method | H61: Stanford CS229 Lecture Notes — Andrew Ng (free PDF) [External] | I61: Ch 6 SVM — Lagrange duality section | J61: 1 | K61: Not started
A62: 56 | B62: 46323 | C62: SVM: margins, hinge loss, dual, kernel trick | D62: 1. Classical ML | E62: Important | F62: 1. CampusX — 100 Days of Machine Learning (YouTube playlist, 134 videos) 2. Interview Question Bank (your project file) | G62: 1. #92 SVM Geometric Intuition · #93 Hard Margin maths · #94 Soft Margin · #95 Kernel Trick intuition · #96 Kernel Trick code 2. §1 SVM & kernels — all 8 Qs | H62: 1. CampusX — Support Vector Machines (SVM) (course, 7 lessons) 2. TuteDude — Generative AI course 3. Stanford CS229 Lecture Notes — Andrew Ng (free PDF) [External] | I62: 1. Only if you want more depth 2. Module 12 — L30 Support Vector Machine 3. Ch 6 Support vector machines | J62: 1.5 | K62: Not started
...

Sheet Coding (day-wise)
A1: Placement Prep — Coding, day-wise (13 Oct–3 Nov · Must + Important) | G1: ="Rows done: "&COUNTIF(L7:L76,"Done")&" / "&COUNTA(L7:L76)&" ("&TEXT(COUNTIF(L7:L76,"Done")/COUNTA(L7:L76),"0%")&")" -> Rows done: 0 / 70 (0%)
A2: Sorted by date. Every day has two tracks: (1) DSA / SQL practice — LeetCode or SQL problems EVERY day; (2) ML / DL coding & projects. SUFFICIENT = must-do; ADD-ON = optional extra.
A3: Method for every problem: say inputs & edge cases → brute force + complexity → optimise → dry-run one example aloud. CWH Python = 11-hr one-shot (timestamps). DSA with Python = your timestamped DSA video.
A4: Red [External] = not in your project files. LeetCode numbers in brackets; premium Meeting Rooms → free LintCode copies. Est. hrs = sufficient part only; edit and the 'Daily load' tab updates.
A6: # | B6: Date | C6: Track | D6: Topic | E6: Syllabus area | F6: Priority | G6: Sufficient resource (full name) | H6: What to follow — sufficient resource | I6: Add-on content resource (full name) | J6: What to follow in add-on resource | K6: Est. hrs | L6: Status | M6: Notes
A7: 1 | B7: 46308 | C7: DSA / SQL practice | D7: Complexity analysis + Arrays & hashing (set 1) | E7: 9. DSA — Python & complexity | F7: Must | G7: 1. DSA with Python — one-shot video (your project file, timestamps) 2. LeetCode / NeetCode 150 (Python) [External] | H7: 1. 04:39–01:32:29 — algorithmic complexity · order of growth · complexity classes · practice Qs 2. Two Sum (1) · Contains Duplicate (217) · Valid Anagram (242) | I7: DSA with Python — one-shot video (your project file, timestamps) | J7: 01:32:29–02:49:52 Arrays & dynamic arrays (build your own list) | K7: 2.75 | L7: Not started
A8: 2 | B8: 46308 | C8: ML / DL coding & projects | D8: Python fluency (part 1): basics → dicts & sets | E8: 9. Python fluency | F8: Must | G8: CodeWithHarry — Python Tutorial for Beginners (11-hr one-shot, YouTube) | H8: Ch 0–5 (00:00–03:09:41): modules & pip, variables, strings, lists & tuples, dictionaries & sets — at 1.5×, do the practice sets | I8: 1. CodeWithHarry — The Ultimate Job Ready Data Science Course 2. TuteDude — Generative AI course | J8: 1. §3 Python Refresher (quick recap) 2. Module 4 — L1–L12 + Assignment A1 | K8: 2.25 | L8: Not started
A9: 3 | B9: 46308 | C9: ML / DL coding & projects | D9: Python fluency (part 2): conditionals, loops, functions, file I/O | E9: 9. Python fluency | F9: Must | G9: CodeWithHarry — Python Tutorial for Beginners (11-hr one-shot, YouTube) | H9: Ch 6–9 (03:09:41–06:42:22) — at 1.5×, do the practice sets | I9: TuteDude — Generative AI course | J9: Module 4 — L13–L25 + Assignments A2–A4 | K9: 2.25 | L9: Not started
A10: 4 | B10: 46309 | C10: DSA / SQL practice | D10: Arrays & hashing (set 2) | E10: 9. DSA — patterns | F10: Must | G10: LeetCode / NeetCode 150 (Python) [External] | H10: Group Anagrams (49) · Top K Frequent Elements (347) · Product of Array Except Self (238) | I10: DSA with Python — one-shot video (your project file, timestamps) | J10: 06:46:14–09:24:04 Hashing — collisions, linear probing, chaining | K10: 1.75 | L10: Not started
A11: 5 | B11: 46309 | C11: ML / DL coding & projects | D11: Python fluency (part 3): advanced Python | E11: 9. Python fluency | F11: Must | G11: CodeWithHarry — Python Tutorial for Beginners (11-hr one-shot, YouTube) | H11: Ch 12–13 (08:15:38–09:30:22): comprehensions, lambda/map/filter, f-strings, etc. | I11: 1. CodeWithHarry — The Ultimate Job Ready Data Science Course 2. TuteDude — Generative AI course | J11: 1. §3 — 'List comprehensions', 'Lambda functions', 'JSON module' 2. Module 4 — L21–L23, L29 + Assignment A6 | K11: 1.5 | L11: Not started
A12: 6 | B12: 46309 | C12: ML / DL coding & projects | D12: PMF sampling, shuffling, simulations | E12: 9. ML from scratch | F12: Must | G12: 1. Interview Question Bank (your project file) 2. LeetCode [External] | H12: 1. §9 Intuit simulate(prob_dict) without NumPy · Intuit in-place shuffle · OLA fair die · Intuit simulate π · Netradyne cointoss → [a,b] 2. Shuffle an Array (384) — Fisher–Yates | I12: — | J12: — | K12: 1.5 | L12: Not started
A13: 7 | B13: 46310 | C13: DSA / SQL practice | D13: Two pointers | E13: 9. DSA — patterns | F13: Must | G13: LeetCode / NeetCode 150 (Python) [External] | H13: Valid Palindrome (125) · Two Sum II (167) · 3Sum (15) · Container With Most Water (11) · Sort Colors (75) | I13: — | J13: — | K13: 2.5 | L13: Not started
A14: 8 | B14: 46310 | C14: ML / DL coding & projects | D14: NumPy: indexing, axis, broadcasting, vectorized maths | E14: 9. NumPy & Pandas (live notebook) | F14: Must | G14: CodeWithHarry — The Ultimate Job Ready Data Science Course | H14: §7 Data Analysis using NumPy — all 7 lectures (87 min) — code along | I14: TuteDude — Generative AI course | J14: Module 7 — NumPy (4 lectures) + Assignment A9 | K14: 2 | L14: Not started
A15: 9 | B15: 46311 | C15: DSA / SQL practice | D15: SQL basics: create, select, update, constraints | E15: 10. SQL | F15: Must | G15: 1. CodeWithHarry — The Ultimate Job Ready Data Science Course 2. LeetCode — SQL 50 study plan [External] | H15: 1. §11 SQL for Data Science — L1–L12 (intro, MySQL, create DB/table, insert, select, update, delete, transactions, constraints) 2. 'Select' group (5 problems) | I15: CampusX — SQL for Data Science (course, 6 lessons) | J15: Alternative / revision | K15: 2 | L15: Not started
A16: 10 | B16: 46311 | C16: ML / DL coding & projects | D16: Pandas: filtering, groupby, merges, pivot | E16: 9. NumPy & Pandas (live notebook) | F16: Must | G16: CodeWithHarry — The Ultimate Job Ready Data Science Course | H16: §8 Data Analysis using Pandas — all 10 lectures (127 min) — code along | I16: 1. TuteDude — Generative AI course 2. CampusX — Pandas (course, 21 lessons) | J16: 1. Module 8 — L1–L9 + Assignment A10 2. Groupby & merge lessons only | K16: 2.5 | L16: Not started
A17: 11 | B17: 46311 | C17: ML / DL coding & projects | D17: Visualisation: Matplotlib & Seaborn | E17: 9. NumPy & Pandas (live notebook) | F17: Must | G17: CodeWithHarry — The Ultimate Job Ready Data Science Course | H17: §9 Data Visualization — all 10 lectures (137 min) — at 1.5× | I17: TuteDude — Generative AI course | J17: Module 9 Matplotlib · Module 10 Seaborn | K17: 1.75 | L17: Not started
A18: 12 | B18: 46312 | C18: DSA / SQL practice | D18: Sliding window (set 1) | E18: 9. DSA — patterns | F18: Must | G18: LeetCode / NeetCode 150 (Python) [External] | H18: Best Time to Buy & Sell Stock (121) · Longest Substring Without Repeating Characters (3) · Longest Repeating Character Replacement (424) | I18: — | J18: — | K18: 1.75 | L18: Not started
... A22: 16 | B22: 46313 | C22: DSA / SQL practice | D22: Sliding window & prefix sums (set 2) | E22: 9. DSA — patterns | F22: Must | G22: LeetCode / NeetCode 150 (Python) [External] | H22: Permutation in String (567) · Maximum Subarray / Kadane (53) · Range Sum Query – Immutable (303) · Subarray Sum Equals K (560) | I22: — | J22: — | K22: 2 | L22: Not started
A23: 17 | B23: 46313 | C23: ML / DL coding & projects | D23: Linear regression from scratch (closed form + GD) in NumPy | E23: 9. ML from scratch | F23: Must | G23: CampusX — 100 Days of Machine Learning (YouTube playlist, 134 videos) | H23: Re-code #51 / #55 / #58 yourself without looking — closed form and batch GD; match sklearn coefficients | I23: — | J23: — | K23: 1.75 | L23: Not started | M23: Observe.AI & Oracle asked exactly this
A24: 18 | B24: 46314 | C24: DSA / SQL practice | D24: GROUP BY / HAVING & aggregates | E24: 10. SQL | F24: Must | G24: 1. CodeWithHarry — The Ultimate Job Ready Data Science Course 2. LeetCode — SQL 50 study plan [External] | H24: 1. §11 — L16 Functions · L20 GROUP BY 2. 'Basic Aggregate Functions' (8) · 'Sorting and Grouping' — first 3 | I24: — | J24: — | K24: 2 | L24: Not started
A25: 19 | B25: 46314 | C25: DSA / SQL practice | D25: Stacks & queues | E25: 9. DSA — patterns | F25: Must | G25: LeetCode / NeetCode 150 (Python) [External] | H25: Valid Parentheses (20) · Min Stack (155) · Daily Temperatures (739) | I25: DSA with Python — one-shot video (your project file, timestamps) | J25: 05:06:27–06:46:14 — stack, bracket problem, celebrity problem, queue using 2 stacks | K25: 1.75 | L25: Not started
A26: 20 | B26: 46314 | C26: ML / DL coding & projects | D26: Logistic regression from scratch | E26: 9. ML from scratch | F26: Must | G26: CampusX — 100 Days of Machine Learning (YouTube playlist, 134 videos) | H26: #75 Logistic Regression Part 5 — GD & code from scratch (re-code yourself) | I26: — | J26: — | K26: 1.5 | L26: Not started
A27: 21 | B27: 46315 | C27: DSA / SQL practice | D27: Subqueries & advanced joins | E27: 10. SQL | F27: Must | G27: 1. CodeWithHarry — The Ultimate Job Ready Data Science Course 2. LeetCode — SQL 50 study plan [External] | H27: 1. §11 — L19 Subqueries 2. 'Sorting and Grouping' — remaining 4 · 'Advanced Select and Joins' (7) | I27: — | J27: — | K27: 2 | L27: Not started
A28: 22 | B28: 46315 | C28: ML / DL coding & projects | D28: Fraud notebook: imbalance, PR-AUC, threshold, XGBoost | E28: Applied ML (scikit-learn) | F28: Must | G28: Kaggle — 'Credit Card Fraud Detection' dataset (mlg-ulb/creditcardfraud) [External] | H28: Pipeline · class_weight vs SMOTE · RF vs XGBoost · PR-AUC · threshold tuning | I28: — | J28: — | K28: 2.5 | L28: Not started
A29: 23 | B29: 46315 | C29: ML / DL coding & projects | D29: Churn notebook: EDA + logistic baseline + metrics | E29: Applied ML (scikit-learn) | F29: Must | G29: Kaggle — 'Telco Customer Churn' dataset (blastchar) [External] | H29: EDA + logistic regression baseline + confusion matrix, PR-AUC | I29: — | J29: — | K29: 1.75 | L29: Not started
A30: 24 | B30: 46316 | C30: DSA / SQL practice | D30: Sorting & binary search (incl. rotated array) | E30: 9. DSA — patterns | F30: Must | G30: 1. DSA with Python — one-shot video (your project file, timestamps) 2. LeetCode / NeetCode 150 (Python) [External] | H30: 1. 09:28:11 Binary Search · 10:57:11 Merge Sort 2. Binary Search (704) · Search in Rotated Sorted Array (33) · Find Minimum in Rotated Sorted Array (153) | I30: DSA with Python — one-shot video (your project file, timestamps) | J30: 09:41:23–10:57:11 Bubble & Selection sort | K30: 2.25 | L30: Not started
A31: 25 | B31: 46316 | C31: ML / DL coding & projects | D31: K-means from scratch; stable softmax | E31: 9. ML from scratch | F31: Must | G31: 1. CampusX — 100 Days of Machine Learning (YouTube playlist, 134 videos) 2. Stanford CS231n notes — Linear Classification [External] | H31: 1. #130 K-Means Clustering From Scratch in Python 2. 'Practical issues: Numeric stability' (subtract max) — code it | I31: — | J31: — | K31: 1.75 | L31: Not started
A32: 26 | B32: 46316 | C32: ML / DL coding & projects | D32: PyTorch basics (part 1): tensors, autograd, training pipeline | E32: DL coding (PyTorch) | F32: Must | G32: CampusX — Practical Deep Learning using PyTorch (course, 14 lessons) | H32: Lessons 1–4 (tensors → autograd → training pipeline → nn.Module) | I32: PyTorch — 'Learn the Basics' tutorial (pytorch.org) [External] | J32: Pages 1–4 | K32: 2.5 | L32: Not started
A33: 27 | B33: 46317 | C33: DSA / SQL practice | D33: Binary search on answer | E33: 9. DSA — patterns | F33: Must | G33: LeetCode / NeetCode 150 (Python) [External] | H33: Search a 2D Matrix (74) · Koko Eating Bananas (875) | I33: — | J33: — | K33: 1.25 | L33: Not started
A34: 28 | B34: 46317 | C34: ML / DL coding & projects | D34: PyTorch basics (part 2): Dataset / DataLoader, ANN | E34: DL coding (PyTorch) | F34: Must | G34: CampusX — Practical Deep Learning using PyTorch (course, 14 lessons) | H34: Lessons 5–7 (Dataset & DataLoader → ANN → optimisation) | I34: 1. PyTorch — 'Learn the Basics' tutorial (pytorch.org) [External] 2. TuteDude — Generative AI course | J34: 1. Pages 5–8 2. Module 17 — L1–L9 ANN project in Keras (optional comparison) | K34: 2.25 | L34: Not started
A35: 29 | B35: 46317 | C35: ML / DL coding & projects | D35: FNN forward / backward in NumPy (2 hidden layers) | E35: 9. ML from scratch | F35: Must | G35: Mitesh M. Khapra — CS7015 Deep Learning, IIT Madras (YouTube videos + slides) | H35: Lecture 4 backprop equations → implement for 2 hidden layers; then the same net in PyTorch (Oracle question) | I35: CampusX — 100 Days of Deep Learning (YouTube playlist, 84 videos) | J35: Video 'Backpropagation Part 2 – The How' (code-along) | K35: 2.25 | L35: Not started
... A40: 34 | B40: 46319 | C40: DSA / SQL practice | D40: Linked lists (set 2) | E40: 9. DSA — patterns | F40: Must | G40: LeetCode / NeetCode 150 (Python) [External] | H40: Linked List Cycle (141) · Remove Nth Node From End (19) · Add Two Numbers (2) | I40: — | J40: — | K40: 1.75 | L40: Not started
A41: 35 | B41: 46319 | C41: ML / DL coding & projects | D41: Self-attention in PyTorch (single → multi-head → causal mask) | E41: 9. ML from scratch | F41: Must | G41: Andrej Karpathy — 'Let's build GPT: from scratch, in code, spelled out' (YouTube) [External] | H41: First ~60 min, then re-code self-attention unit on your own | I41: — | J41: — | K41: 2.25 | L41: Not started | M41: Cerebras & OLA asked live
A42: 36 | B42: 46320 | C42: DSA / SQL practice | D42: Window functions | E42: 10. SQL | F42: Must | G42: 1. CampusX — SQL Interview Questions (playlist, 1 video) 2. Mode — SQL Tutorial [External] 3. LeetCode [External] | H42: 1. The single video 2. 'SQL Window Functions' page 3. Second Highest Salary (176) · Rank Scores (178) | I42: — | J42: — | K42: 2 | L42: Not started
A43: 37 | B43: 46320 | C43: DSA / SQL practice | D43: Intervals | E43: 9. DSA — patterns | F43: Must | G43: LeetCode / NeetCode 150 (Python) [External] | H43: Merge Intervals (56) · Insert Interval (57) · Non-overlapping Intervals (435) | I43: — | J43: — | K43: 1.5 | L43: Not started
A44: 38 | B44: 46320 | C44: ML / DL coding & projects | D44: CNNs & transfer learning in PyTorch | E44: CV coding (projects) | F44: Must | G44: CampusX — Practical Deep Learning using PyTorch (course, 14 lessons) | H44: CNN lesson + transfer-learning lesson | I44: CampusX — Image Processing Using OpenCV (playlist, 13 videos) | J44: Selective — resizing, flipping, blurring (Razorpay asked) | K44: 2 | L44: Not started
A45: 39 | B45: 46321 | C45: DSA / SQL practice | D45: Window functions (practice) | E45: 10. SQL | F45: Must | G45: LeetCode [External] | H45: Consecutive Numbers (180) · Department Top Three Salaries (185) | I45: — | J45: — | K45: 1 | L45: Not started
A46: 40 | B46: 46321 | C46: DSA / SQL practice | D46: Trees: traversals (set 1) | E46: 9. DSA — patterns | F46: Must | G46: LeetCode / NeetCode 150 (Python) [External] | H46: Max Depth (104) · Invert Tree (226) · Inorder Traversal (94) · Level Order (102) | I46: CampusX — Binary Search Tree (playlist, 1 video) | J46: The single video | K46: 2 | L46: Not started
A47: 41 | B47: 46321 | C47: ML / DL coding & projects | D47: Project 1 — CIFAR-10 (part 1): baseline CNN + augmentation | E47: CV coding (projects) | F47: Must | G47: PyTorch tutorial — 'Training a Classifier' (CIFAR-10) [External] | H47: Baseline CNN (conv → BN → ReLU → pool), augmentation | I47: — | J47: — | K47: 2.5 | L47: Not started
A48: 42 | B48: 46321 | C48: ML / DL coding & projects | D48: Project 1 — CIFAR-10 (part 2): ResNet-18 transfer learning + README | E48: CV coding (projects) | F48: Must | G48: PyTorch tutorial — 'Transfer Learning for Computer Vision' [External] | H48: Fine-tune ResNet-18; compare accuracy, params, time; README + GitHub | I48: — | J48: — | K48: 2.25 | L48: Not started
...

Sheet Daily load
A1: Daily load check — hours per day (from the Est. hrs columns)
A2: All cells below are formulas. Change an estimate or move a row to another date in the Theory / Coding tabs and these totals update.
A4: Date | B4: Theory hrs | C4: DSA / SQL practice hrs | D4: ML / DL coding hrs | E4: Total hrs | F4: Theory topics | G4: Practice items | H4: Rows done | I4: Rows total | J4: % done
A5: 46308 | B5: =SUMIFS('Theory (day-wise)'!$J$7:$J$83,'Theory (day-wise)'!$B$7:$B$83,$A5) -> 4.75 | C5: =SUMIFS('Coding (day-wise)'!$K$7:$K$76,'Coding (day-wise)'!$B$7:$B$76,$A5,'Coding (day-wise)'!$C$7:$C$76,"DSA / SQL practice") -> 2.75 | D5: =SUMIFS('Coding (day-wise)'!$K$7:$K$76,'Coding (day-wise)'!$B$7:$B$76,$A5,'Coding (day-wise)'!$C$7:$C$76,"ML / DL coding & projects") -> 4.5 | E5: =SUM(B5:D5) -> 12 | F5: =COUNTIFS('Theory (day-wise)'!$B$7:$B$83,$A5) -> 2 | G5: =COUNTIFS('Coding (day-wise)'!$B$7:$B$76,$A5,'Coding (day-wise)'!$C$7:$C$76,"DSA / SQL practice") -> 1 | H5: =COUNTIFS('Theory (day-wise)'!$B$7:$B$83,$A5,'Theory (day-wise)'!$K$7:$K$83,"Done")+COUNTIFS('Coding (day-wise)'!$B$7:$B$76,$A5,'Coding (day-wise)'!$L$7:$L$76,"Done") -> 0 | I5: =F5+COUNTIFS('Coding (day-wise)'!$B$7:$B$76,$A5) -> 5 | J5: =IF(I5=0,0,H5/I5) -> 0
A6: 46309 | B6: =SUMIFS('Theory (day-wise)'!$J$7:$J$83,'Theory (day-wise)'!$B$7:$B$83,$A6) -> 7 | C6: =SUMIFS('Coding (day-wise)'!$K$7:$K$76,'Coding (day-wise)'!$B$7:$B$76,$A6,'Coding (day-wise)'!$C$7:$C$76,"DSA / SQL practice") -> 1.75 | D6: =SUMIFS('Coding (day-wise)'!$K$7:$K$76,'Coding (day-wise)'!$B$7:$B$76,$A6,'Coding (day-wise)'!$C$7:$C$76,"ML / DL coding & projects") -> 3 | E6: =SUM(B6:D6) -> 11.75 | F6: =COUNTIFS('Theory (day-wise)'!$B$7:$B$83,$A6) -> 4 | G6: =COUNTIFS('Coding (day-wise)'!$B$7:$B$76,$A6,'Coding (day-wise)'!$C$7:$C$76,"DSA / SQL practice") -> 1 | H6: =COUNTIFS('Theory (day-wise)'!$B$7:$B$83,$A6,'Theory (day-wise)'!$K$7:$K$83,"Done")+COUNTIFS('Coding (day-wise)'!$B$7:$B$76,$A6,'Coding (day-wise)'!$L$7:$L$76,"Done") -> 0 | I6: =F6+COUNTIFS('Coding (day-wise)'!$B$7:$B$76,$A6) -> 7 | J6: =IF(I6=0,0,H6/I6) -> 0
A7: 46310 | B7: =SUMIFS('Theory (day-wise)'!$J$7:$J$83,'Theory (day-wise)'!$B$7:$B$83,$A7) -> 7 | C7: =SUMIFS('Coding (day-wise)'!$K$7:$K$76,'Coding (day-wise)'!$B$7:$B$76,$A7,'Coding (day-wise)'!$C$7:$C$76,"DSA / SQL practice") -> 2.5 | D7: =SUMIFS('Coding (day-wise)'!$K$7:$K$76,'Coding (day-wise)'!$B$7:$B$76,$A7,'Coding (day-wise)'!$C$7:$C$76,"ML / DL coding & projects") -> 2 | E7: =SUM(B7:D7) -> 11.5 | F7: =COUNTIFS('Theory (day-wise)'!$B$7:$B$83,$A7) -> 4 | G7: =COUNTIFS('Coding (day-wise)'!$B$7:$B$76,$A7,'Coding (day-wise)'!$C$7:$C$76,"DSA / SQL practice") -> 1 | H7: =COUNTIFS('Theory (day-wise)'!$B$7:$B$83,$A7,'Theory (day-wise)'!$K$7:$K$83,"Done")+COUNTIFS('Coding (day-wise)'!$B$7:$B$76,$A7,'Coding (day-wise)'!$L$7:$L$76,"Done") -> 0 | I7: =F7+COUNTIFS('Coding (day-wise)'!$B$7:$B$76,$A7) -> 6 | J7: =IF(I7=0,0,H7/I7) -> 0
A8: 46311 | B8: =SUMIFS('Theory (day-wise)'!$J$7:$J$83,'Theory (day-wise)'!$B$7:$B$83,$A8) -> 6 | C8: =SUMIFS('Coding (day-wise)'!$K$7:$K$76,'Coding (day-wise)'!$B$7:$B$76,$A8,'Coding (day-wise)'!$C$7:$C$76,"DSA / SQL practice") -> 2 | D8: =SUMIFS('Coding (day-wise)'!$K$7:$K$76,'Coding (day-wise)'!$B$7:$B$76,$A8,'Coding (day-wise)'!$C$7:$C$76,"ML / DL coding & projects") -> 4.25 | E8: =SUM(B8:D8) -> 12.25 | F8: =COUNTIFS('Theory (day-wise)'!$B$7:$B$83,$A8) -> 2 | G8: =COUNTIFS('Coding (day-wise)'!$B$7:$B$76,$A8,'Coding (day-wise)'!$C$7:$C$76,"DSA / SQL practice") -> 1 | H8: =COUNTIFS('Theory (day-wise)'!$B$7:$B$83,$A8,'Theory (day-wise)'!$K$7:$K$83,"Done")+COUNTIFS('Coding (day-wise)'!$B$7:$B$76,$A8,'Coding (day-wise)'!$L$7:$L$76,"Done") -> 0 | I8: =F8+COUNTIFS('Coding (day-wise)'!$B$7:$B$76,$A8) -> 5 | J8: =IF(I8=0,0,H8/I8) -> 0
A9: 46312 | B9: =SUMIFS('Theory (day-wise)'!$J$7:$J$83,'Theory (day-wise)'!$B$7:$B$83,$A9) -> 6.5 | C9: =SUMIFS('Coding (day-wise)'!$K$7:$K$76,'Coding (day-wise)'!$B$7:$B$76,$A9,'Coding (day-wise)'!$C$7:$C$76,"DSA / SQL practice") -> 1.75 | D9: =SUMIFS('Coding (day-wise)'!$K$7:$K$76,'Coding (day-wise)'!$B$7:$B$76,$A9,'Coding (day-wise)'!$C$7:$C$76,"ML / DL coding & projects") -> 4.25 | E9: =SUM(B9:D9) -> 12.5 | F9: =COUNTIFS('Theory (day-wise)'!$B$7:$B$83,$A9) -> 3 | G9: =COUNTIFS('Coding (day-wise)'!$B$7:$B$76,$A9,'Coding (day-wise)'!$C$7:$C$76,"DSA / SQL practice") -> 1 | H9: =COUNTIFS('Theory (day-wise)'!$B$7:$B$83,$A9,'Theory (day-wise)'!$K$7:$K$83,"Done")+COUNTIFS('Coding (day-wise)'!$B$7:$B$76,$A9,'Coding (day-wise)'!$L$7:$L$76,"Done") -> 0 | I9: =F9+COUNTIFS('Coding (day-wise)'!$B$7:$B$76,$A9) -> 6 | J9: =IF(I9=0,0,H9/I9) -> 0
A10: 46313 | B10: =SUMIFS('Theory (day-wise)'!$J$7:$J$83,'Theory (day-wise)'!$B$7:$B$83,$A10) -> 6.75 | C10: =SUMIFS('Coding (day-wise)'!$K$7:$K$76,'Coding (day-wise)'!$B$7:$B$76,$A10,'Coding (day-wise)'!$C$7:$C$76,"DSA / SQL practice") -> 4 | D10: =SUMIFS('Coding (day-wise)'!$K$7:$K$76,'Coding (day-wise)'!$B$7:$B$76,$A10,'Coding (day-wise)'!$C$7:$C$76,"ML / DL coding & projects") -> 1.75 | E10: =SUM(B10:D10) -> 12.5 | F10: =COUNTIFS('Theory (day-wise)'!$B$7:$B$83,$A10) -> 5 | G10: =COUNTIFS('Coding (day-wise)'!$B$7:$B$76,$A10,'Coding (day-wise)'!$C$7:$C$76,"DSA / SQL practice") -> 2 | H10: =COUNTIFS('Theory (day-wise)'!$B$7:$B$83,$A10,'Theory (day-wise)'!$K$7:$K$83,"Done")+COUNTIFS('Coding (day-wise)'!$B$7:$B$76,$A10,'Coding (day-wise)'!$L$7:$L$76,"Done") -> 0 | I10: =F10+COUNTIFS('Coding (day-wise)'!$B$7:$B$76,$A10) -> 8 | J10: =IF(I10=0,0,H10/I10) -> 0
A11: 46314 | B11: =SUMIFS('Theory (day-wise)'!$J$7:$J$83,'Theory (day-wise)'!$B$7:$B$83,$A11) -> 7.25 | C11: =SUMIFS('Coding (day-wise)'!$K$7:$K$76,'Coding (day-wise)'!$B$7:$B$76,$A11,'Coding (day-wise)'!$C$7:$C$76,"DSA / SQL practice") -> 3.75 | D11: =SUMIFS('Coding (day-wise)'!$K$7:$K$76,'Coding (day-wise)'!$B$7:$B$76,$A11,'Coding (day-wise)'!$C$7:$C$76,"ML / DL coding & projects") -> 1.5 | E11: =SUM(B11:D11) -> 12.5 | F11: =COUNTIFS('Theory (day-wise)'!$B$7:$B$83,$A11) -> 3 | G11: =COUNTIFS('Coding (day-wise)'!$B$7:$B$76,$A11,'Coding (day-wise)'!$C$7:$C$76,"DSA / SQL practice") -> 2 | H11: =COUNTIFS('Theory (day-wise)'!$B$7:$B$83,$A11,'Theory (day-wise)'!$K$7:$K$83,"Done")+COUNTIFS('Coding (day-wise)'!$B$7:$B$76,$A11,'Coding (day-wise)'!$L$7:$L$76,"Done") -> 0 | I11: =F11+COUNTIFS('Coding (day-wise)'!$B$7:$B$76,$A11) -> 6 | J11: =IF(I11=0,0,H11/I11) -> 0
A12: 46315 | B12: =SUMIFS('Theory (day-wise)'!$J$7:$J$83,'Theory (day-wise)'!$B$7:$B$83,$A12) -> 6 | C12: =SUMIFS('Coding (day-wise)'!$K$7:$K$76,'Coding (day-wise)'!$B$7:$B$76,$A12,'Coding (day-wise)'!$C$7:$C$76,"DSA / SQL practice") -> 2 | D12: =SUMIFS('Coding (day-wise)'!$K$7:$K$76,'Coding (day-wise)'!$B$7:$B$76,$A12,'Coding (day-wise)'!$C$7:$C$76,"ML / DL coding & projects") -> 4.25 | E12: =SUM(B12:D12) -> 12.25 | F12: =COUNTIFS('Theory (day-wise)'!$B$7:$B$83,$A12) -> 4 | G12: =COUNTIFS('Coding (day-wise)'!$B$7:$B$76,$A12,'Coding (day-wise)'!$C$7:$C$76,"DSA / SQL practice") -> 1 | H12: =COUNTIFS('Theory (day-wise)'!$B$7:$B$83,$A12,'Theory (day-wise)'!$K$7:$K$83,"Done")+COUNTIFS('Coding (day-wise)'!$B$7:$B$76,$A12,'Coding (day-wise)'!$L$7:$L$76,"Done") -> 0 | I12: =F12+COUNTIFS('Coding (day-wise)'!$B$7:$B$76,$A12) -> 7 | J12: =IF(I12=0,0,H12/I12) -> 0
A13: 46316 | B13: =SUMIFS('Theory (day-wise)'!$J$7:$J$83,'Theory (day-wise)'!$B$7:$B$83,$A13) -> 6 | C13: =SUMIFS('Coding (day-wise)'!$K$7:$K$76,'Coding (day-wise)'!$B$7:$B$76,$A13,'Coding (day-wise)'!$C$7:$C$76,"DSA / SQL practice") -> 2.25 | D13: =SUMIFS('Coding (day-wise)'!$K$7:$K$76,'Coding (day-wise)'!$B$7:$B$76,$A13,'Coding (day-wise)'!$C$7:$C$76,"ML / DL coding & projects") -> 4.25 | E13: =SUM(B13:D13) -> 12.5 | F13: =COUNTIFS('Theory (day-wise)'!$B$7:$B$83,$A13) -> 5 | G13: =COUNTIFS('Coding (day-wise)'!$B$7:$B$76,$A13,'Coding (day-wise)'!$C$7:$C$76,"DSA / SQL practice") -> 1 | H13: =COUNTIFS('Theory (day-wise)'!$B$7:$B$83,$A13,'Theory (day-wise)'!$K$7:$K$83,"Done")+COUNTIFS('Coding (day-wise)'!$B$7:$B$76,$A13,'Coding (day-wise)'!$L$7:$L$76,"Done") -> 0 | I13: =F13+COUNTIFS('Coding (day-wise)'!$B$7:$B$76,$A13) -> 8 | J13: =IF(I13=0,0,H13/I13) -> 0
A14: 46317 | B14: =SUMIFS('Theory (day-wise)'!$J$7:$J$83,'Theory (day-wise)'!$B$7:$B$83,$A14) -> 6.5 | C14: =SUMIFS('Coding (day-wise)'!$K$7:$K$76,'Coding (day-wise)'!$B$7:$B$76,$A14,'Coding (day-wise)'!$C$7:$C$76,"DSA / SQL practice") -> 1.25 | D14: =SUMIFS('Coding (day-wise)'!$K$7:$K$76,'Coding (day-wise)'!$B$7:$B$76,$A14,'Coding (day-wise)'!$C$7:$C$76,"ML / DL coding & projects") -> 4.5 | E14: =SUM(B14:D14) -> 12.25 | F14: =COUNTIFS('Theory (day-wise)'!$B$7:$B$83,$A14) -> 4 | G14: =COUNTIFS('Coding (day-wise)'!$B$7:$B$76,$A14,'Coding (day-wise)'!$C$7:$C$76,"DSA / SQL practice") -> 1 | H14: =COUNTIFS('Theory (day-wise)'!$B$7:$B$83,$A14,'Theory (day-wise)'!$K$7:$K$83,"Done")+COUNTIFS('Coding (day-wise)'!$B$7:$B$76,$A14,'Coding (day-wise)'!$L$7:$L$76,"Done") -> 0 | I14: =F14+COUNTIFS('Coding (day-wise)'!$B$7:$B$76,$A14) -> 7 | J14: =IF(I14=0,0,H14/I14) -> 0
A15: 46318 | B15: =SUMIFS('Theory (day-wise)'!$J$7:$J$83,'Theory (day-wise)'!$B$7:$B$83,$A15) -> 4.75 | C15: =SUMIFS('Coding (day-wise)'!$K$7:$K$76,'Coding (day-wise)'!$B$7:$B$76,$A15,'Coding (day-wise)'!$C$7:$C$76,"DSA / SQL practice") -> 2 | D15: =SUMIFS('Coding (day-wise)'!$K$7:$K$76,'Coding (day-wise)'!$B$7:$B$76,$A15,'Coding (day-wise)'!$C$7:$C$76,"ML / DL coding & projects") -> 4.75 | E15: =SUM(B15:D15) -> 11.5 | F15: =COUNTIFS('Theory (day-wise)'!$B$7:$B$83,$A15) -> 2 | G15: =COUNTIFS('Coding (day-wise)'!$B$7:$B$76,$A15,'Coding (day-wise)'!$C$7:$C$76,"DSA / SQL practice") -> 1 | H15: =COUNTIFS('Theory (day-wise)'!$B$7:$B$83,$A15,'Theory (day-wise)'!$K$7:$K$83,"Done")+COUNTIFS('Coding (day-wise)'!$B$7:$B$76,$A15,'Coding (day-wise)'!$L$7:$L$76,"Done") -> 0 | I15: =F15+COUNTIFS('Coding (day-wise)'!$B$7:$B$76,$A15) -> 5 | J15: =IF(I15=0,0,H15/I15) -> 0
A16: 46319 | B16: =SUMIFS('Theory (day-wise)'!$J$7:$J$83,'Theory (day-wise)'!$B$7:$B$83,$A16) -> 6.75 | C16: =SUMIFS('Coding (day-wise)'!$K$7:$K$76,'Coding (day-wise)'!$B$7:$B$76,$A16,'Coding (day-wise)'!$C$7:$C$76,"DSA / SQL practice") -> 3.5 | D16: =SUMIFS('Coding (day-wise)'!$K$7:$K$76,'Coding (day-wise)'!$B$7:$B$76,$A16,'Coding (day-wise)'!$C$7:$C$76,"ML / DL coding & projects") -> 2.25 | E16: =SUM(B16:D16) -> 12.5 | F16: =COUNTIFS('Theory (day-wise)'!$B$7:$B$83,$A16) -> 4 | G16: =COUNTIFS('Coding (day-wise)'!$B$7:$B$76,$A16,'Coding (day-wise)'!$C$7:$C$76,"DSA / SQL practice") -> 2 | H16: =COUNTIFS('Theory (day-wise)'!$B$7:$B$83,$A16,'Theory (day-wise)'!$K$7:$K$83,"Done")+COUNTIFS('Coding (day-wise)'!$B$7:$B$76,$A16,'Coding (day-wise)'!$L$7:$L$76,"Done") -> 0 | I16: =F16+COUNTIFS('Coding (day-wise)'!$B$7:$B$76,$A16) -> 7 | J16: =IF(I16=0,0,H16/I16) -> 0
... A26: 46329 | B26: =SUMIFS('Theory (day-wise)'!$J$7:$J$83,'Theory (day-wise)'!$B$7:$B$83,$A26) -> 4.75 | C26: =SUMIFS('Coding (day-wise)'!$K$7:$K$76,'Coding (day-wise)'!$B$7:$B$76,$A26,'Coding (day-wise)'!$C$7:$C$76,"DSA / SQL practice") -> 3.5 | D26: =SUMIFS('Coding (day-wise)'!$K$7:$K$76,'Coding (day-wise)'!$B$7:$B$76,$A26,'Coding (day-wise)'!$C$7:$C$76,"ML / DL coding & projects") -> 4.25 | E26: =SUM(B26:D26) -> 12.5 | F26: =COUNTIFS('Theory (day-wise)'!$B$7:$B$83,$A26) -> 3 | G26: =COUNTIFS('Coding (day-wise)'!$B$7:$B$76,$A26,'Coding (day-wise)'!$C$7:$C$76,"DSA / SQL practice") -> 2 | H26: =COUNTIFS('Theory (day-wise)'!$B$7:$B$83,$A26,'Theory (day-wise)'!$K$7:$K$83,"Done")+COUNTIFS('Coding (day-wise)'!$B$7:$B$76,$A26,'Coding (day-wise)'!$L$7:$L$76,"Done") -> 0 | I26: =F26+COUNTIFS('Coding (day-wise)'!$B$7:$B$76,$A26) -> 7 | J26: =IF(I26=0,0,H26/I26) -> 0
A27: Total | B27: =SUM(B5:B26) -> 131.5 | C27: =SUM(C5:C26) -> 60.75 | D27: =SUM(D5:D26) -> 75.5 | E27: =SUM(E5:E26) -> 267.75 | F27: =SUM(F5:F26) -> 77 | G27: =SUM(G5:G26) -> 33 | H27: =SUM(H5:H26) -> 0 | I27: =SUM(I5:I26) -> 147 | J27: =IF(I27=0,0,H27/I27) -> 0
A28: Average / day | B28: =AVERAGE(B5:B26) -> 5.9772727 | C28: =AVERAGE(C5:C26) -> 2.7613636 | D28: =AVERAGE(D5:D26) -> 3.4318182 | E28: =AVERAGE(E5:E26) -> 12.170455
A29: Min / Max total | E29: =TEXT(MIN(E5:E26),"0.00")&" – "&TEXT(MAX(E5:E26),"0.00") -> 11.50 – 12.50
